<!-- Inverted Pendulum Description
This is a description of the inverted pendulum model.
The original description (code) can be found at: https://github.com/openai/gym/blob/master/gym/envs/mujoco/assets/inverted_pendulum.xml.
Modified by A. Ali.

Warning: Do not make any modifications to the code in "inverted_pendulum.xml" or "utils.py".
-->
<mujoco model="inverted pendulum">
	<compiler inertiafromgeom="true"/>
	<default>
		<joint armature="0" damping="1" limited="true"/>
		<geom contype="0" friction="1 0.1 0.1" rgba="0.7 0.7 0 1"/>
		<tendon/>
		<motor ctrlrange="-3 3"/>
	</default>
	<option gravity="1e-5 0 -9.81" integrator="RK4" timestep="0.02"/>
	<size nstack="3000"/>
	<worldbody>
		<geom name="rail" pos="0 0 0" quat="0.707 0 0.707 0" rgba="1 0 0 1" size="0.02 1"  type="capsule"/>
		<body name="cart" pos="0 0 0">
			<joint axis="1 0 0" limited="true" name="joint0" pos="0 0 0" range="-1 1" type="slide"/>
			<geom name="cart" pos="0 0 0" quat="0.707 0 0.707 0" size="0.1 0.1" type="capsule"/>
			<body name="pole" pos="0 0 0">
				<joint axis="0 1 0" name="joint1" pos="0 0 0" range="-90 90" type="hinge"/>
				<geom fromto="0 0 0 0.001 0 0.6" name="cpole" rgba="0.1 1.0 0.1 1"  size="0.049 0.3" type="capsule"/>
			</body>
		</body>
	</worldbody>
	<actuator>
		<motor ctrllimited="true" ctrlrange="-3 3" gear="100" joint="joint0" name="linear_joint"/>
	</actuator>
</mujoco>